Workbook

Sheet Índice
A1: Veedores y Coordinadores por Recinto – Cantón Latacunga
A2: Recintos y juntas: CNE, Distributivo de Recintos Electorales, corte al 11 de agosto de 2026 (Seccionales y CPCCS 2027)
A4: Parroquia | B4: Tipo | C4: N° recintos | D4: N° juntas (JRV)
A5: Eloy Alfaro (San Felipe) | B5: Urbana | C5: 7 | D5: 91
A6: Ignacio Flores | B6: Urbana | C6: 5 | D6: 55
A7: Juan Montalvo (San Sebastián) | B7: Urbana | C7: 5 | D7: 48
A8: La Matriz | B8: Urbana | C8: 8 | D8: 76
A9: San Buenaventura | B9: Urbana | C9: 2 | D9: 17
A10: Aláquez | B10: Rural | C10: 2 | D10: 19
A11: Belisario Quevedo | B11: Rural | C11: 2 | D11: 15
A12: Guaytacama | B12: Rural | C12: 1 | D12: 25
A13: Joséguango Bajo (Santa Marianita) | B13: Rural | C13: 1 | D13: 6
A14: Mulaló | B14: Rural | C14: 3 | D14: 23
A15: Once de Noviembre (Ilinchisí) | B15: Rural | C15: 1 | D15: 7
A16: Poaló | B16: Rural | C16: 2 | D16: 15
... A19: Toacaso | B19: Rural | C19: 3 | D19: 31
A20: TOTAL LATACUNGA | C20: 49 | D20: 492
A22: La numeración de juntas (N° JRV) sigue exactamente al CNE. Ver la pestaña "Verificado" para el cruce recinto por recinto.

Sheet Eloy Alfaro (San Felipe)
A1: Parroquia Eloy Alfaro (San Felipe) — Cantón Latacunga
A3: COORDINADORES POR RECINTO
A4: N° | B4: Recinto electoral | C4: Dirección | D4: N° de Juntas (JRV) | E4: N° de electores | F4: Nombre del coordinador | G4: Cédula | H4: Teléfono | I4: Observaciones
A5: 1 | B5: ESC. DE EDUCACION BASICA CLUB ROTARIO | C5: ALBERTO VAREA QUEVEDO Y DEMETRIO AGUILERA MALTA | D5: 12 | E5: 4200
A6: 2 | B6: U.E. JORGE ICAZA | C6: TANICUCHI Y SAQUISILI- SALCEDO | D6: 12 | E6: 4200
A7: 3 | B7: U.E. JUAN ABEL ECHEVERRIA | C7: AV SIMON RODRIGUEZ Y HONDURAS | D7: 13 | E7: 4550
A8: 4 | B8: U. E. LIC. JAIME ANDRADE FABARA | C8: RIO YANAYACHO Y RIO PITA | D8: 12 | E8: 4200
A9: 5 | B9: U.E. MONSEÑOR LEONIDAS PROAÑO/LATACUNGA | C9: AV INDOAMÉRICA Y MEXICO | D9: 8 | E9: 2800
A10: 6 | B10: U.E. ANA PAEZ MANUEL SALCEDO/ ESCUELA MANUEL SALCEDO | C10: AV. IVERO AMERICANO Y AV. 5 DE JUNIO | D10: 10 | E10: 3500
A11: 7 | B11: U.E. ANA PAEZ MANUEL SALCEDO/ ESCUELA ANA PAEZ | C11: AV. MANUEL TERAN AV. 5 DE JUNIO | D11: 24 | E11: 8123
A13: VEEDORES POR JUNTA RECEPTORA DEL VOTO (JRV)
A14: N° JRV | B14: Recinto electoral | D14: Nombre del veedor | E14: Cédula | F14: Teléfono | G14: Observaciones
A15: 1F | B15: ESC. DE EDUCACION BASICA CLUB ROTARIO
A16: 2F | B16: ESC. DE EDUCACION BASICA CLUB ROTARIO
A17: 3F | B17: ESC. DE EDUCACION BASICA CLUB ROTARIO
A18: 4F | B18: ESC. DE EDUCACION BASICA CLUB ROTARIO
A19: 5F | B19: ESC. DE EDUCACION BASICA CLUB ROTARIO
A20: 6F | B20: ESC. DE EDUCACION BASICA CLUB ROTARIO
A21: 7F | B21: ESC. DE EDUCACION BASICA CLUB ROTARIO
A22: 1M | B22: ESC. DE EDUCACION BASICA CLUB ROTARIO
A23: 2M | B23: ESC. DE EDUCACION BASICA CLUB ROTARIO
A24: 3M | B24: ESC. DE EDUCACION BASICA CLUB ROTARIO
A25: 4M | B25: ESC. DE EDUCACION BASICA CLUB ROTARIO
A26: 5M | B26: ESC. DE EDUCACION BASICA CLUB ROTARIO
... A105: 44M | B105: U.E. ANA PAEZ MANUEL SALCEDO/ ESCUELA ANA PAEZ

Sheet Ignacio Flores
A1: Parroquia Ignacio Flores — Cantón Latacunga
A3: COORDINADORES POR RECINTO
A4: N° | B4: Recinto electoral | C4: Dirección | D4: N° de Juntas (JRV) | E4: N° de electores | F4: Nombre del coordinador | G4: Cédula | H4: Teléfono | I4: Observaciones
A5: 1 | B5: U.E. LUIS FERNANDO RUIZ | C5: AV. TRAJANO NARANJO Y 11 DE NOVIEMBRE | D5: 16 | E5: 5600
A6: 2 | B6: U.E. 11 DE NOVIEMBRE | C6: SANTIAGO ZAMORA Y AV. RUMIÑAHUI Y ATAHUALPA | D6: 14 | E6: 4900
A7: 3 | B7: U.E. JOSE MARIA VELASCO IBARRA | C7: QUITO Y ATAHUALPA | D7: 9 | E7: 3150
A8: 4 | B8: UNIDAD EDUCATIVA RAMON BARBA NARANJO/ CENTRO | C8: AV. UNIDAD NACIONAL Y AV. RUMIÑAHUI | D8: 14 | E8: 4659
A9: 5 | B9: UNIDAD EDUCATIVA INTERCULTURAL BILINGUE SUMAK KAWSAY | C9: VIA PALOPO | D9: 2 | E9: 286
A11: VEEDORES POR JUNTA RECEPTORA DEL VOTO (JRV)
A12: N° JRV | B12: Recinto electoral | D12: Nombre del veedor | E12: Cédula | F12: Teléfono | G12: Observaciones
A13: 1F | B13: U.E. LUIS FERNANDO RUIZ
A14: 2F | B14: U.E. LUIS FERNANDO RUIZ
A15: 3F | B15: U.E. LUIS FERNANDO RUIZ
A16: 4F | B16: U.E. LUIS FERNANDO RUIZ
A17: 5F | B17: U.E. LUIS FERNANDO RUIZ
A18: 6F | B18: U.E. LUIS FERNANDO RUIZ
A19: 7F | B19: U.E. LUIS FERNANDO RUIZ
A20: 8F | B20: U.E. LUIS FERNANDO RUIZ
A21: 9F | B21: U.E. LUIS FERNANDO RUIZ
A22: 1M | B22: U.E. LUIS FERNANDO RUIZ
A23: 2M | B23: U.E. LUIS FERNANDO RUIZ
A24: 3M | B24: U.E. LUIS FERNANDO RUIZ
... A67: 1M | B67: UNIDAD EDUCATIVA INTERCULTURAL BILINGUE SUMAK KAWSAY

Sheet Juan Montalvo (San Sebastián)
A1: Parroquia Juan Montalvo (San Sebastián) — Cantón Latacunga
A3: COORDINADORES POR RECINTO
A4: N° | B4: Recinto electoral | C4: Dirección | D4: N° de Juntas (JRV) | E4: N° de electores | F4: Nombre del coordinador | G4: Cédula | H4: Teléfono | I4: Observaciones
A5: 1 | B5: U.E. VICENTE LEON (LA COCHA) | C5: AV. TAHUANTINSUYO Y CARANQUIS | D5: 14 | E5: 4900
A6: 2 | B6: UNIDAD EDUCATIVA JOSÉ MARÍA VELAZ | C6: ISLA SEYMOUR Y GUAYAQUIL | D6: 8 | E6: 2800
A7: 3 | B7: UNIDAD EDUCATIVA LUIS FERNANDO VIVERO | C7: CALLE ISLA SEYMOUR Y JUAN ABEL ECHEVERIA | D7: 10 | E7: 3500
A8: 4 | B8: U.E. SEMILLITAS DE VIDA | C8: GRAL. PROAÑO Y QUIJANO Y ORDOÑEZ | D8: 8 | E8: 2800
A9: 5 | B9: SINDICATO DE CHOFERES DE COTOPAXI | C9: QUIJANO Y ORDOÑEZ Y FELIZ VALENCIA | D9: 8 | E9: 2488
A11: VEEDORES POR JUNTA RECEPTORA DEL VOTO (JRV)
A12: N° JRV | B12: Recinto electoral | D12: Nombre del veedor | E12: Cédula | F12: Teléfono | G12: Observaciones
A13: 1F | B13: U.E. VICENTE LEON (LA COCHA)
A14: 2F | B14: U.E. VICENTE LEON (LA COCHA)
A15: 3F | B15: U.E. VICENTE LEON (LA COCHA)
A16: 4F | B16: U.E. VICENTE LEON (LA COCHA)
A17: 5F | B17: U.E. VICENTE LEON (LA COCHA)
A18: 6F | B18: U.E. VICENTE LEON (LA COCHA)
A19: 7F | B19: U.E. VICENTE LEON (LA COCHA)
A20: 8F | B20: U.E. VICENTE LEON (LA COCHA)
A21: 1M | B21: U.E. VICENTE LEON (LA COCHA)
A22: 2M | B22: U.E. VICENTE LEON (LA COCHA)
A23: 3M | B23: U.E. VICENTE LEON (LA COCHA)
A24: 4M | B24: U.E. VICENTE LEON (LA COCHA)
... A60: 23M | B60: SINDICATO DE CHOFERES DE COTOPAXI

Sheet La Matriz
A1: Parroquia La Matriz — Cantón Latacunga
A3: COORDINADORES POR RECINTO
A4: N° | B4: Recinto electoral | C4: Dirección | D4: N° de Juntas (JRV) | E4: N° de electores | F4: Nombre del coordinador | G4: Cédula | H4: Teléfono | I4: Observaciones
A5: 1 | B5: U.E. LA INMACULADA | C5: ANTONIA VELA Y TARQUI | D5: 8 | E5: 2800
A6: 2 | B6: U.E. PCEI VICENTE LEÓN Y ARGUELLES / COL. VICENTE LEON DEL CENTRO | C6: BELISARIO QUEVEDO Y GRAL. PROAÑO | D6: 8 | E6: 2800
A7: 3 | B7: U.E. PARTICULAR SAN JOSE LA SALLE | C7: QUIJANO Y ORDOÑEZ Y GRAL. MALDONADO | D7: 8 | E7: 2800
A8: 4 | B8: U.E. VICTORIA VASCONEZ CUVI | C8: FELIX VALENCIA Y SANCHEZ DE ORELLANA ENTRE QUITO | D8: 12 | E8: 4200
A9: 5 | B9: U. E. ISIDRO AYORA | C9: QUIJANO Y ORDOÑEZ Y TARQUI | D9: 8 | E9: 2800
A10: 6 | B10: U.E. PRIMERO DE ABRIL | C10: AV.ORIENTE Y HERMANAS PAEZ | D10: 8 | E10: 2800
A11: 7 | B11: U.E. VICTORIA VASCONEZ CUVI / ELVIRA ORTEGA - SUR | C11: SANCHEZ DE ORELLANA Y FELIX VALENCIA Y QUITO | D11: 16 | E11: 5600
A12: 8 | B12: U.E. VASCONEZ CUVI / SIMON BOLIVAR BLOQUE NORTE | C12: CALIXTO PINO Y SANCHEZ DE ORELLANA | D12: 8 | E12: 2811
A14: VEEDORES POR JUNTA RECEPTORA DEL VOTO (JRV)
A15: N° JRV | B15: Recinto electoral | D15: Nombre del veedor | E15: Cédula | F15: Teléfono | G15: Observaciones
A16: 1F | B16: U.E. LA INMACULADA
A17: 2F | B17: U.E. LA INMACULADA
A18: 3F | B18: U.E. LA INMACULADA
A19: 4F | B19: U.E. LA INMACULADA
A20: 1M | B20: U.E. LA INMACULADA
A21: 2M | B21: U.E. LA INMACULADA
A22: 3M | B22: U.E. LA INMACULADA
A23: 4M | B23: U.E. LA INMACULADA
A24: 5F | B24: U.E. PCEI VICENTE LEÓN Y ARGUELLES / COL. VICENTE LEON DEL CENTRO
A25: 6F | B25: U.E. PCEI VICENTE LEÓN Y ARGUELLES / COL. VICENTE LEON DEL CENTRO
A26: 7F | B26: U.E. PCEI VICENTE LEÓN Y ARGUELLES / COL. VICENTE LEON DEL CENTRO
A27: 8F | B27: U.E. PCEI VICENTE LEÓN Y ARGUELLES / COL. VICENTE LEON DEL CENTRO
... A91: 36M | B91: U.E. VASCONEZ CUVI / SIMON BOLIVAR BLOQUE NORTE

Sheet San Buenaventura
A1: Parroquia San Buenaventura — Cantón Latacunga
A3: COORDINADORES POR RECINTO
A4: N° | B4: Recinto electoral | C4: Dirección | D4: N° de Juntas (JRV) | E4: N° de electores | F4: Nombre del coordinador | G4: Cédula | H4: Teléfono | I4: Observaciones
A5: 1 | B5: ESC. DE EDUCACION BASICA NUMA POMPILIO LLONA | C5: SAN BARTOLOME Y AV. SAN AGUSTIN | D5: 7 | E5: 2450
A6: 2 | B6: U.E. 14 DE JULIO - JUAN ABEL ECHEVERRIA | C6: AV. MIGUEL ITURRALDE Y LAS AGUILAS | D6: 10 | E6: 3393
A8: VEEDORES POR JUNTA RECEPTORA DEL VOTO (JRV)
A9: N° JRV | B9: Recinto electoral | D9: Nombre del veedor | E9: Cédula | F9: Teléfono | G9: Observaciones
A10: 1F | B10: ESC. DE EDUCACION BASICA NUMA POMPILIO LLONA
A11: 2F | B11: ESC. DE EDUCACION BASICA NUMA POMPILIO LLONA
A12: 3F | B12: ESC. DE EDUCACION BASICA NUMA POMPILIO LLONA
A13: 4F | B13: ESC. DE EDUCACION BASICA NUMA POMPILIO LLONA
A14: 1M | B14: ESC. DE EDUCACION BASICA NUMA POMPILIO LLONA
A15: 2M | B15: ESC. DE EDUCACION BASICA NUMA POMPILIO LLONA
A16: 3M | B16: ESC. DE EDUCACION BASICA NUMA POMPILIO LLONA
A17: 5F | B17: U.E. 14 DE JULIO - JUAN ABEL ECHEVERRIA
A18: 6F | B18: U.E. 14 DE JULIO - JUAN ABEL ECHEVERRIA
A19: 7F | B19: U.E. 14 DE JULIO - JUAN ABEL ECHEVERRIA
A20: 8F | B20: U.E. 14 DE JULIO - JUAN ABEL ECHEVERRIA
A21: 9F | B21: U.E. 14 DE JULIO - JUAN ABEL ECHEVERRIA
... A26: 8M | B26: U.E. 14 DE JULIO - JUAN ABEL ECHEVERRIA

Sheet Aláquez
A1: Parroquia Aláquez — Cantón Latacunga
A3: COORDINADORES POR RECINTO
A4: N° | B4: Recinto electoral | C4: Dirección | D4: N° de Juntas (JRV) | E4: N° de electores | F4: Nombre del coordinador | G4: Cédula | H4: Teléfono | I4: Observaciones
A5: 1 | B5: U.E. MANUEL GONZALO ALBAN RUMAZO / ESC. ABDON CALDERON | C5: VICENTE LEON Y ARCENTALES | D5: 10 | E5: 3500
A6: 2 | B6: U.E. MANUEL GONZALO ALBÁN RUMAZO - BLOQUE DOS | C6: MANUEL ARCENTALES ALBERTO YANEZ | D6: 9 | E6: 2968
A8: VEEDORES POR JUNTA RECEPTORA DEL VOTO (JRV)
A9: N° JRV | B9: Recinto electoral | D9: Nombre del veedor | E9: Cédula | F9: Teléfono | G9: Observaciones
A10: 1F | B10: U.E. MANUEL GONZALO ALBAN RUMAZO / ESC. ABDON CALDERON
A11: 2F | B11: U.E. MANUEL GONZALO ALBAN RUMAZO / ESC. ABDON CALDERON
A12: 3F | B12: U.E. MANUEL GONZALO ALBAN RUMAZO / ESC. ABDON CALDERON
A13: 4F | B13: U.E. MANUEL GONZALO ALBAN RUMAZO / ESC. ABDON CALDERON
A14: 5F | B14: U.E. MANUEL GONZALO ALBAN RUMAZO / ESC. ABDON CALDERON
A15: 1M | B15: U.E. MANUEL GONZALO ALBAN RUMAZO / ESC. ABDON CALDERON
A16: 2M | B16: U.E. MANUEL GONZALO ALBAN RUMAZO / ESC. ABDON CALDERON
A17: 3M | B17: U.E. MANUEL GONZALO ALBAN RUMAZO / ESC. ABDON CALDERON
A18: 4M | B18: U.E. MANUEL GONZALO ALBAN RUMAZO / ESC. ABDON CALDERON
A19: 5M | B19: U.E. MANUEL GONZALO ALBAN RUMAZO / ESC. ABDON CALDERON
A20: 6F | B20: U.E. MANUEL GONZALO ALBÁN RUMAZO - BLOQUE DOS
A21: 7F | B21: U.E. MANUEL GONZALO ALBÁN RUMAZO - BLOQUE DOS
... A28: 9M | B28: U.E. MANUEL GONZALO ALBÁN RUMAZO - BLOQUE DOS

Sheet Belisario Quevedo
A1: Parroquia Belisario Quevedo — Cantón Latacunga
A3: COORDINADORES POR RECINTO
A4: N° | B4: Recinto electoral | C4: Dirección | D4: N° de Juntas (JRV) | E4: N° de electores | F4: Nombre del coordinador | G4: Cédula | H4: Teléfono | I4: Observaciones
A5: 1 | B5: U.E. BELISARIO QUEVEDO | C5: 24 DE MAYO Y DR. RAUL LEON MENDEZ | D5: 8 | E5: 2800
A6: 2 | B6: U.E. BELISARIO QUEVEDO / BLOQUE DOS | C6: BRUNO ZAMBONINO Y 24 DE MAYO | D6: 7 | E6: 2193
A8: VEEDORES POR JUNTA RECEPTORA DEL VOTO (JRV)
A9: N° JRV | B9: Recinto electoral | D9: Nombre del veedor | E9: Cédula | F9: Teléfono | G9: Observaciones
A10: 1F | B10: U.E. BELISARIO QUEVEDO
A11: 2F | B11: U.E. BELISARIO QUEVEDO
A12: 3F | B12: U.E. BELISARIO QUEVEDO
A13: 4F | B13: U.E. BELISARIO QUEVEDO
A14: 1M | B14: U.E. BELISARIO QUEVEDO
A15: 2M | B15: U.E. BELISARIO QUEVEDO
A16: 3M | B16: U.E. BELISARIO QUEVEDO
A17: 4M | B17: U.E. BELISARIO QUEVEDO
A18: 5F | B18: U.E. BELISARIO QUEVEDO / BLOQUE DOS
A19: 6F | B19: U.E. BELISARIO QUEVEDO / BLOQUE DOS
A20: 7F | B20: U.E. BELISARIO QUEVEDO / BLOQUE DOS
A21: 8F | B21: U.E. BELISARIO QUEVEDO / BLOQUE DOS
... A24: 7M | B24: U.E. BELISARIO QUEVEDO / BLOQUE DOS

Sheet Guaytacama
A1: Parroquia Guaytacama — Cantón Latacunga
A3: COORDINADORES POR RECINTO
A4: N° | B4: Recinto electoral | C4: Dirección | D4: N° de Juntas (JRV) | E4: N° de electores | F4: Nombre del coordinador | G4: Cédula | H4: Teléfono | I4: Observaciones
A5: 1 | B5: U.E. SAN JOSE DE GUAYTACAMA | C5: JUAN MONTALVO | D5: 25 | E5: 8391
A7: VEEDORES POR JUNTA RECEPTORA DEL VOTO (JRV)
A8: N° JRV | B8: Recinto electoral | D8: Nombre del veedor | E8: Cédula | F8: Teléfono | G8: Observaciones
A9: 1F | B9: U.E. SAN JOSE DE GUAYTACAMA
A10: 2F | B10: U.E. SAN JOSE DE GUAYTACAMA
A11: 3F | B11: U.E. SAN JOSE DE GUAYTACAMA
A12: 4F | B12: U.E. SAN JOSE DE GUAYTACAMA
A13: 5F | B13: U.E. SAN JOSE DE GUAYTACAMA
A14: 6F | B14: U.E. SAN JOSE DE GUAYTACAMA
A15: 7F | B15: U.E. SAN JOSE DE GUAYTACAMA
A16: 8F | B16: U.E. SAN JOSE DE GUAYTACAMA
A17: 9F | B17: U.E. SAN JOSE DE GUAYTACAMA
A18: 10F | B18: U.E. SAN JOSE DE GUAYTACAMA
A19: 11F | B19: U.E. SAN JOSE DE GUAYTACAMA
A20: 12F | B20: U.E. SAN JOSE DE GUAYTACAMA
... A33: 12M | B33: U.E. SAN JOSE DE GUAYTACAMA

Sheet Joséguango Bajo (Santa Marianit
A1: Parroquia Joséguango Bajo (Santa Marianita) — Cantón Latacunga
A3: COORDINADORES POR RECINTO
A4: N° | B4: Recinto electoral | C4: Dirección | D4: N° de Juntas (JRV) | E4: N° de electores | F4: Nombre del coordinador | G4: Cédula | H4: Teléfono | I4: Observaciones
A5: 1 | B5: U.E. FELIX VALENCIA | C5: Av. de los Incas e Isabel Eastman | D5: 6 | E5: 1758
A7: VEEDORES POR JUNTA RECEPTORA DEL VOTO (JRV)
A8: N° JRV | B8: Recinto electoral | D8: Nombre del veedor | E8: Cédula | F8: Teléfono | G8: Observaciones
A9: 1F | B9: U.E. FELIX VALENCIA
A10: 2F | B10: U.E. FELIX VALENCIA
A11: 3F | B11: U.E. FELIX VALENCIA
A12: 1M | B12: U.E. FELIX VALENCIA
A13: 2M | B13: U.E. FELIX VALENCIA
A14: 3M | B14: U.E. FELIX VALENCIA

Sheet Mulaló
A1: Parroquia Mulaló — Cantón Latacunga
A3: COORDINADORES POR RECINTO
A4: N° | B4: Recinto electoral | C4: Dirección | D4: N° de Juntas (JRV) | E4: N° de electores | F4: Nombre del coordinador | G4: Cédula | H4: Teléfono | I4: Observaciones
A5: 1 | B5: UNIDAD EDUCATIVA MULALO / Esc. JUAN PIO MONTUFAR | C5: SAN FRANCISCO 4 DE OCTUBRE | D5: 8 | E5: 2800
A6: 2 | B6: UNIDAD EDUCATIVA MULALO / COLEGIO TÉCNICO MULALÓ | C6: 4 DE OCTUBRE Y RUMIÑAHUI | D6: 8 | E6: 2800
A7: 3 | B7: UNIDAD EDUCATIVA MULALO / BLOQUE TRES | C7: ATAHUALPA Y LA LIBERTAD | D7: 7 | E7: 2270
A9: VEEDORES POR JUNTA RECEPTORA DEL VOTO (JRV)
A10: N° JRV | B10: Recinto electoral | D10: Nombre del veedor | E10: Cédula | F10: Teléfono | G10: Observaciones
A11: 1F | B11: UNIDAD EDUCATIVA MULALO / Esc. JUAN PIO MONTUFAR
A12: 2F | B12: UNIDAD EDUCATIVA MULALO / Esc. JUAN PIO MONTUFAR
A13: 3F | B13: UNIDAD EDUCATIVA MULALO / Esc. JUAN PIO MONTUFAR
A14: 4F | B14: UNIDAD EDUCATIVA MULALO / Esc. JUAN PIO MONTUFAR
A15: 1M | B15: UNIDAD EDUCATIVA MULALO / Esc. JUAN PIO MONTUFAR
A16: 2M | B16: UNIDAD EDUCATIVA MULALO / Esc. JUAN PIO MONTUFAR
A17: 3M | B17: UNIDAD EDUCATIVA MULALO / Esc. JUAN PIO MONTUFAR
A18: 4M | B18: UNIDAD EDUCATIVA MULALO / Esc. JUAN PIO MONTUFAR
A19: 5F | B19: UNIDAD EDUCATIVA MULALO / COLEGIO TÉCNICO MULALÓ
A20: 6F | B20: UNIDAD EDUCATIVA MULALO / COLEGIO TÉCNICO MULALÓ
A21: 7F | B21: UNIDAD EDUCATIVA MULALO / COLEGIO TÉCNICO MULALÓ
A22: 8F | B22: UNIDAD EDUCATIVA MULALO / COLEGIO TÉCNICO MULALÓ
... A33: 11M | B33: UNIDAD EDUCATIVA MULALO / BLOQUE TRES

Sheet Once de Noviembre (Ilinchisí)
A1: Parroquia Once de Noviembre (Ilinchisí) — Cantón Latacunga
A3: COORDINADORES POR RECINTO
A4: N° | B4: Recinto electoral | C4: Dirección | D4: N° de Juntas (JRV) | E4: N° de electores | F4: Nombre del coordinador | G4: Cédula | H4: Teléfono | I4: Observaciones
A5: 1 | B5: UNIDAD EDUCATIVA LATACUNGA | C5: 10 DE AGOSTO Y ILLINCHIZI | D5: 7 | E5: 2145
A7: VEEDORES POR JUNTA RECEPTORA DEL VOTO (JRV)
A8: N° JRV | B8: Recinto electoral | D8: Nombre del veedor | E8: Cédula | F8: Teléfono | G8: Observaciones
A9: 1F | B9: UNIDAD EDUCATIVA LATACUNGA
A10: 2F | B10: UNIDAD EDUCATIVA LATACUNGA
A11: 3F | B11: UNIDAD EDUCATIVA LATACUNGA
A12: 4F | B12: UNIDAD EDUCATIVA LATACUNGA
A13: 1M | B13: UNIDAD EDUCATIVA LATACUNGA
A14: 2M | B14: UNIDAD EDUCATIVA LATACUNGA
A15: 3M | B15: UNIDAD EDUCATIVA LATACUNGA

Sheet Poaló
A1: Parroquia Poaló — Cantón Latacunga
A3: COORDINADORES POR RECINTO
A4: N° | B4: Recinto electoral | C4: Dirección | D4: N° de Juntas (JRV) | E4: N° de electores | F4: Nombre del coordinador | G4: Cédula | H4: Teléfono | I4: Observaciones
A5: 1 | B5: GAD PARROQUIAL COLISEO POALO | C5: RUPERTO REINOSO Y SEÑOR DE MACAS | D5: 4 | E5: 1400
A6: 2 | B6: UNIDAD EDUCATIVA POALO GARCIA MORENO / BLOQUE 2 | C6: SALACHE Y 19 DE MARZO | D6: 11 | E6: 3641
A8: VEEDORES POR JUNTA RECEPTORA DEL VOTO (JRV)
A9: N° JRV | B9: Recinto electoral | D9: Nombre del veedor | E9: Cédula | F9: Teléfono | G9: Observaciones
A10: 1F | B10: GAD PARROQUIAL COLISEO POALO
A11: 2F | B11: GAD PARROQUIAL COLISEO POALO
A12: 1M | B12: GAD PARROQUIAL COLISEO POALO
A13: 2M | B13: GAD PARROQUIAL COLISEO POALO
A14: 3F | B14: UNIDAD EDUCATIVA POALO GARCIA MORENO / BLOQUE 2
A15: 4F | B15: UNIDAD EDUCATIVA POALO GARCIA MORENO / BLOQUE 2
A16: 5F | B16: UNIDAD EDUCATIVA POALO GARCIA MORENO / BLOQUE 2
A17: 6F | B17: UNIDAD EDUCATIVA POALO GARCIA MORENO / BLOQUE 2
A18: 7F | B18: UNIDAD EDUCATIVA POALO GARCIA MORENO / BLOQUE 2
A19: 8F | B19: UNIDAD EDUCATIVA POALO GARCIA MORENO / BLOQUE 2
A20: 3M | B20: UNIDAD EDUCATIVA POALO GARCIA MORENO / BLOQUE 2
A21: 4M | B21: UNIDAD EDUCATIVA POALO GARCIA MORENO / BLOQUE 2
... A24: 7M | B24: UNIDAD EDUCATIVA POALO GARCIA MORENO / BLOQUE 2

Sheet San Juan de Pastocalle
A1: Parroquia San Juan de Pastocalle — Cantón Latacunga
A3: COORDINADORES POR RECINTO
A4: N° | B4: Recinto electoral | C4: Dirección | D4: N° de Juntas (JRV) | E4: N° de electores | F4: Nombre del coordinador | G4: Cédula | H4: Teléfono | I4: Observaciones
A5: 1 | B5: UNIDAD EDUCATIVA COMUNITARIA BILINGUE. EL SEMBRADOR | C5: 9 DE OCTUBRE Y 24 DE JUNIO | D5: 8 | E5: 2800
A6: 2 | B6: U.E. PASTOCALLE / BLOQUE 2 | C6: 24 DE MAYO/PASAJE | D6: 9 | E6: 3150
A7: 3 | B7: U.E. PASTOCALLE / COLEGIO PASTOCALLE | C7: 24 DE MAYO | D7: 10 | E7: 3371
A8: 4 | B8: U.E. ATANASIO VITERI KAROLYS | C8: CENTRO DE LA COMUNIDAD | D8: 2 | E8: 327
A10: VEEDORES POR JUNTA RECEPTORA DEL VOTO (JRV)
A11: N° JRV | B11: Recinto electoral | D11: Nombre del veedor | E11: Cédula | F11: Teléfono | G11: Observaciones
A12: 1F | B12: UNIDAD EDUCATIVA COMUNITARIA BILINGUE. EL SEMBRADOR
A13: 2F | B13: UNIDAD EDUCATIVA COMUNITARIA BILINGUE. EL SEMBRADOR
A14: 3F | B14: UNIDAD EDUCATIVA COMUNITARIA BILINGUE. EL SEMBRADOR
A15: 4F | B15: UNIDAD EDUCATIVA COMUNITARIA BILINGUE. EL SEMBRADOR
A16: 1M | B16: UNIDAD EDUCATIVA COMUNITARIA BILINGUE. EL SEMBRADOR
A17: 2M | B17: UNIDAD EDUCATIVA COMUNITARIA BILINGUE. EL SEMBRADOR
A18: 3M | B18: UNIDAD EDUCATIVA COMUNITARIA BILINGUE. EL SEMBRADOR
A19: 4M | B19: UNIDAD EDUCATIVA COMUNITARIA BILINGUE. EL SEMBRADOR
A20: 5F | B20: U.E. PASTOCALLE / BLOQUE 2
A21: 6F | B21: U.E. PASTOCALLE / BLOQUE 2
A22: 7F | B22: U.E. PASTOCALLE / BLOQUE 2
A23: 8F | B23: U.E. PASTOCALLE / BLOQUE 2
... A40: 1M | B40: U.E. ATANASIO VITERI KAROLYS

Sheet Tanicuchí
A1: Parroquia Tanicuchí — Cantón Latacunga
A3: COORDINADORES POR RECINTO
A4: N° | B4: Recinto electoral | C4: Dirección | D4: N° de Juntas (JRV) | E4: N° de electores | F4: Nombre del coordinador | G4: Cédula | H4: Teléfono | I4: Observaciones
A5: 1 | B5: U.E. MARCO AURELIO SUBIA MARTINEZ- BATALLA DE PANUPALI / COLEGIO MARCO AURELIO SUBIA MARTINEZ | C5: JUAN MANUEL LASSO Y LEONIDAS PLAZA | D5: 16 | E5: 5600
A6: 2 | B6: U. E. MARCO AURELIO SUBIA MARTINEZ BATALLA DE PANUPALI / ESC.BATALLA DE PANUPALI | C6: JUAN MANUEL LASSO Y LEONIDAS PLAZA | D6: 12 | E6: 4200
A7: 3 | B7: CENTRO. INTERCULTURAL COMUNITARIO TANICUCHI | C7: LEONIDAS PLAZA Y GENERAL ALBERTO ENRIQUE GALLO | D7: 7 | E7: 1997
A9: VEEDORES POR JUNTA RECEPTORA DEL VOTO (JRV)
A10: N° JRV | B10: Recinto electoral | D10: Nombre del veedor | E10: Cédula | F10: Teléfono | G10: Observaciones
A11: 1F | B11: U.E. MARCO AURELIO SUBIA MARTINEZ- BATALLA DE PANUPALI / COLEGIO MARCO AURELIO SUBIA MARTINEZ
A12: 2F | B12: U.E. MARCO AURELIO SUBIA MARTINEZ- BATALLA DE PANUPALI / COLEGIO MARCO AURELIO SUBIA MARTINEZ
A13: 3F | B13: U.E. MARCO AURELIO SUBIA MARTINEZ- BATALLA DE PANUPALI / COLEGIO MARCO AURELIO SUBIA MARTINEZ
A14: 4F | B14: U.E. MARCO AURELIO SUBIA MARTINEZ- BATALLA DE PANUPALI / COLEGIO MARCO AURELIO SUBIA MARTINEZ
A15: 5F | B15: U.E. MARCO AURELIO SUBIA MARTINEZ- BATALLA DE PANUPALI / COLEGIO MARCO AURELIO SUBIA MARTINEZ
A16: 6F | B16: U.E. MARCO AURELIO SUBIA MARTINEZ- BATALLA DE PANUPALI / COLEGIO MARCO AURELIO SUBIA MARTINEZ
A17: 7F | B17: U.E. MARCO AURELIO SUBIA MARTINEZ- BATALLA DE PANUPALI / COLEGIO MARCO AURELIO SUBIA MARTINEZ
A18: 8F | B18: U.E. MARCO AURELIO SUBIA MARTINEZ- BATALLA DE PANUPALI / COLEGIO MARCO AURELIO SUBIA MARTINEZ
A19: 1M | B19: U.E. MARCO AURELIO SUBIA MARTINEZ- BATALLA DE PANUPALI / COLEGIO MARCO AURELIO SUBIA MARTINEZ
A20: 2M | B20: U.E. MARCO AURELIO SUBIA MARTINEZ- BATALLA DE PANUPALI / COLEGIO MARCO AURELIO SUBIA MARTINEZ
A21: 3M | B21: U.E. MARCO AURELIO SUBIA MARTINEZ- BATALLA DE PANUPALI / COLEGIO MARCO AURELIO SUBIA MARTINEZ
A22: 4M | B22: U.E. MARCO AURELIO SUBIA MARTINEZ- BATALLA DE PANUPALI / COLEGIO MARCO AURELIO SUBIA MARTINEZ
... A45: 17M | B45: CENTRO. INTERCULTURAL COMUNITARIO TANICUCHI

Sheet Toacaso
A1: Parroquia Toacaso — Cantón Latacunga
A3: COORDINADORES POR RECINTO
A4: N° | B4: Recinto electoral | C4: Dirección | D4: N° de Juntas (JRV) | E4: N° de electores | F4: Nombre del coordinador | G4: Cédula | H4: Teléfono | I4: Observaciones
A5: 1 | B5: U.E. TOACASO BLOQUE 3 - ESC. SIMON RODRIGUEZ | C5: COTOPAXI Y PICHINCHA | D5: 10 | E5: 3500
A6: 2 | B6: U.E. TOACASO - COL. TÉCNICO TOACASO | C6: CALLE ORIENTE Y POLICARPA TINAJERO | D6: 10 | E6: 3500
A7: 3 | B7: U.E. TOACASO BLOQUE 2 | C7: PICHINCHA Y COTOPAXI | D7: 11 | E7: 3306
A9: VEEDORES POR JUNTA RECEPTORA DEL VOTO (JRV)
A10: N° JRV | B10: Recinto electoral | D10: Nombre del veedor | E10: Cédula | F10: Teléfono | G10: Observaciones
A11: 1F | B11: U.E. TOACASO BLOQUE 3 - ESC. SIMON RODRIGUEZ
A12: 2F | B12: U.E. TOACASO BLOQUE 3 - ESC. SIMON RODRIGUEZ
A13: 3F | B13: U.E. TOACASO BLOQUE 3 - ESC. SIMON RODRIGUEZ
A14: 4F | B14: U.E. TOACASO BLOQUE 3 - ESC. SIMON RODRIGUEZ
A15: 5F | B15: U.E. TOACASO BLOQUE 3 - ESC. SIMON RODRIGUEZ
A16: 1M | B16: U.E. TOACASO BLOQUE 3 - ESC. SIMON RODRIGUEZ
A17: 2M | B17: U.E. TOACASO BLOQUE 3 - ESC. SIMON RODRIGUEZ
A18: 3M | B18: U.E. TOACASO BLOQUE 3 - ESC. SIMON RODRIGUEZ
A19: 4M | B19: U.E. TOACASO BLOQUE 3 - ESC. SIMON RODRIGUEZ
A20: 5M | B20: U.E. TOACASO BLOQUE 3 - ESC. SIMON RODRIGUEZ
A21: 6F | B21: U.E. TOACASO - COL. TÉCNICO TOACASO
A22: 7F | B22: U.E. TOACASO - COL. TÉCNICO TOACASO
... A41: 15M | B41: U.E. TOACASO BLOQUE 2

Sheet Verificado
A1: Verificación de Juntas Receptoras del Voto contra el CNE — Cantón Latacunga
A2: Fuente: CNE, Distributivo de Recintos Electorales — Elecciones Seccionales y CPCCS 2027, corte al 11 de agosto de 2026. Las columnas "CNE" son datos fijos del distributivo; las columnas "Matriz" se calculan en vivo leyendo cada hoja de parroquia.
A3: El CNE numera las juntas por parroquia (y por zona, donde existe), con numeración separada para femeninas (F) y masculinas (M). Cada junta se identifica como 1F, 2F… (femeninas) y 1M, 2M… (masculinas), dentro de su parroquia y zona.
A5: RESUMEN POR PARROQUIA
A6: Parroquia (hoja) | B6: Recintos CNE | C6: Recintos verificados | D6: Juntas CNE | E6: Juntas en matriz | F6: Estado
A7: Eloy Alfaro (San Felipe) | B7: =COUNTIF($A$26:$A$74,A7) -> 7 | C7: =COUNTIFS($A$26:$A$74,A7,$P$26:$P$74,"✔ Verificado") -> 0 | D7: =SUMIFS($G$26:$G$74,$A$26:$A$74,A7)+SUMIFS($I$26:$I$74,$A$26:$A$74,A7) -> 91 | E7: =COUNTIF('Eloy Alfaro (San Felipe)'!$A$15:$A$105,"*F")+COUNTIF('Eloy Alfaro (San Felipe)'!$A$15:$A$105,"*M") -> 91 | F7: =IF(AND(B7=C7,D7=E7),"✔ Verificado","✖ Revisar") -> ✖ Revisar
A8: Ignacio Flores | B8: =COUNTIF($A$26:$A$74,A8) -> 5 | C8: =COUNTIFS($A$26:$A$74,A8,$P$26:$P$74,"✔ Verificado") -> 0 | D8: =SUMIFS($G$26:$G$74,$A$26:$A$74,A8)+SUMIFS($I$26:$I$74,$A$26:$A$74,A8) -> 55 | E8: =COUNTIF('Ignacio Flores'!$A$13:$A$67,"*F")+COUNTIF('Ignacio Flores'!$A$13:$A$67,"*M") -> 55 | F8: =IF(AND(B8=C8,D8=E8),"✔ Verificado","✖ Revisar") -> ✖ Revisar
A9: Juan Montalvo (San Sebastián) | B9: =COUNTIF($A$26:$A$74,A9) -> 5 | C9: =COUNTIFS($A$26:$A$74,A9,$P$26:$P$74,"✔ Verificado") -> 0 | D9: =SUMIFS($G$26:$G$74,$A$26:$A$74,A9)+SUMIFS($I$26:$I$74,$A$26:$A$74,A9) -> 48 | E9: =COUNTIF('Juan Montalvo (San Sebastián)'!$A$13:$A$60,"*F")+COUNTIF('Juan Montalvo (San Sebastián)'!$A$13:$A$60,"*M") -> 48 | F9: =IF(AND(B9=C9,D9=E9),"✔ Verificado","✖ Revisar") -> ✖ Revisar
A10: La Matriz | B10: =COUNTIF($A$26:$A$74,A10) -> 8 | C10: =COUNTIFS($A$26:$A$74,A10,$P$26:$P$74,"✔ Verificado") -> 0 | D10: =SUMIFS($G$26:$G$74,$A$26:$A$74,A10)+SUMIFS($I$26:$I$74,$A$26:$A$74,A10) -> 76 | E10: =COUNTIF('La Matriz'!$A$16:$A$91,"*F")+COUNTIF('La Matriz'!$A$16:$A$91,"*M") -> 76 | F10: =IF(AND(B10=C10,D10=E10),"✔ Verificado","✖ Revisar") -> ✖ Revisar
A11: San Buenaventura | B11: =COUNTIF($A$26:$A$74,A11) -> 2 | C11: =COUNTIFS($A$26:$A$74,A11,$P$26:$P$74,"✔ Verificado") -> 0 | D11: =SUMIFS($G$26:$G$74,$A$26:$A$74,A11)+SUMIFS($I$26:$I$74,$A$26:$A$74,A11) -> 17 | E11: =COUNTIF('San Buenaventura'!$A$10:$A$26,"*F")+COUNTIF('San Buenaventura'!$A$10:$A$26,"*M") -> 17 | F11: =IF(AND(B11=C11,D11=E11),"✔ Verificado","✖ Revisar") -> ✖ Revisar
A12: Aláquez | B12: =COUNTIF($A$26:$A$74,A12) -> 2 | C12: =COUNTIFS($A$26:$A$74,A12,$P$26:$P$74,"✔ Verificado") -> 0 | D12: =SUMIFS($G$26:$G$74,$A$26:$A$74,A12)+SUMIFS($I$26:$I$74,$A$26:$A$74,A12) -> 19 | E12: =COUNTIF(Aláquez!$A$10:$A$28,"*F")+COUNTIF(Aláquez!$A$10:$A$28,"*M") -> 19 | F12: =IF(AND(B12=C12,D12=E12),"✔ Verificado","✖ Revisar") -> ✖ Revisar
A13: Belisario Quevedo | B13: =COUNTIF($A$26:$A$74,A13) -> 2 | C13: =COUNTIFS($A$26:$A$74,A13,$P$26:$P$74,"✔ Verificado") -> 0 | D13: =SUMIFS($G$26:$G$74,$A$26:$A$74,A13)+SUMIFS($I$26:$I$74,$A$26:$A$74,A13) -> 15 | E13: =COUNTIF('Belisario Quevedo'!$A$10:$A$24,"*F")+COUNTIF('Belisario Quevedo'!$A$10:$A$24,"*M") -> 15 | F13: =IF(AND(B13=C13,D13=E13),"✔ Verificado","✖ Revisar") -> ✖ Revisar
A14: Guaytacama | B14: =COUNTIF($A$26:$A$74,A14) -> 1 | C14: =COUNTIFS($A$26:$A$74,A14,$P$26:$P$74,"✔ Verificado") -> 0 | D14: =SUMIFS($G$26:$G$74,$A$26:$A$74,A14)+SUMIFS($I$26:$I$74,$A$26:$A$74,A14) -> 25 | E14: =COUNTIF(Guaytacama!$A$9:$A$33,"*F")+COUNTIF(Guaytacama!$A$9:$A$33,"*M") -> 25 | F14: =IF(AND(B14=C14,D14=E14),"✔ Verificado","✖ Revisar") -> ✖ Revisar
A15: Joséguango Bajo (Santa Marianit | B15: =COUNTIF($A$26:$A$74,A15) -> 1 | C15: =COUNTIFS($A$26:$A$74,A15,$P$26:$P$74,"✔ Verificado") -> 0 | D15: =SUMIFS($G$26:$G$74,$A$26:$A$74,A15)+SUMIFS($I$26:$I$74,$A$26:$A$74,A15) -> 6 | E15: =COUNTIF('Joséguango Bajo (Santa Marianit'!$A$9:$A$14,"*F")+COUNTIF('Joséguango Bajo (Santa Marianit'!$A$9:$A$14,"*M") -> 6 | F15: =IF(AND(B15=C15,D15=E15),"✔ Verificado","✖ Revisar") -> ✖ Revisar
A16: Mulaló | B16: =COUNTIF($A$26:$A$74,A16) -> 3 | C16: =COUNTIFS($A$26:$A$74,A16,$P$26:$P$74,"✔ Verificado") -> 0 | D16: =SUMIFS($G$26:$G$74,$A$26:$A$74,A16)+SUMIFS($I$26:$I$74,$A$26:$A$74,A16) -> 23 | E16: =COUNTIF(Mulaló!$A$11:$A$33,"*F")+COUNTIF(Mulaló!$A$11:$A$33,"*M") -> 23 | F16: =IF(AND(B16=C16,D16=E16),"✔ Verificado","✖ Revisar") -> ✖ Revisar
A17: Once de Noviembre (Ilinchisí) | B17: =COUNTIF($A$26:$A$74,A17) -> 1 | C17: =COUNTIFS($A$26:$A$74,A17,$P$26:$P$74,"✔ Verificado") -> 0 | D17: =SUMIFS($G$26:$G$74,$A$26:$A$74,A17)+SUMIFS($I$26:$I$74,$A$26:$A$74,A17) -> 7 | E17: =COUNTIF('Once de Noviembre (Ilinchisí)'!$A$9:$A$15,"*F")+COUNTIF('Once de Noviembre (Ilinchisí)'!$A$9:$A$15,"*M") -> 7 | F17: =IF(AND(B17=C17,D17=E17),"✔ Verificado","✖ Revisar") -> ✖ Revisar
A18: Poaló | B18: =COUNTIF($A$26:$A$74,A18) -> 2 | C18: =COUNTIFS($A$26:$A$74,A18,$P$26:$P$74,"✔ Verificado") -> 0 | D18: =SUMIFS($G$26:$G$74,$A$26:$A$74,A18)+SUMIFS($I$26:$I$74,$A$26:$A$74,A18) -> 15 | E18: =COUNTIF(Poaló!$A$10:$A$24,"*F")+COUNTIF(Poaló!$A$10:$A$24,"*M") -> 15 | F18: =IF(AND(B18=C18,D18=E18),"✔ Verificado","✖ Revisar") -> ✖ Revisar
A19: San Juan de Pastocalle | B19: =COUNTIF($A$26:$A$74,A19) -> 4 | C19: =COUNTIFS($A$26:$A$74,A19,$P$26:$P$74,"✔ Verificado") -> 0 | D19: =SUMIFS($G$26:$G$74,$A$26:$A$74,A19)+SUMIFS($I$26:$I$74,$A$26:$A$74,A19) -> 29 | E19: =COUNTIF('San Juan de Pastocalle'!$A$12:$A$40,"*F")+COUNTIF('San Juan de Pastocalle'!$A$12:$A$40,"*M") -> 29 | F19: =IF(AND(B19=C19,D19=E19),"✔ Verificado","✖ Revisar") -> ✖ Revisar
A20: Tanicuchí | B20: =COUNTIF($A$26:$A$74,A20) -> 3 | C20: =COUNTIFS($A$26:$A$74,A20,$P$26:$P$74,"✔ Verificado") -> 0 | D20: =SUMIFS($G$26:$G$74,$A$26:$A$74,A20)+SUMIFS($I$26:$I$74,$A$26:$A$74,A20) -> 35 | E20: =COUNTIF(Tanicuchí!$A$11:$A$45,"*F")+COUNTIF(Tanicuchí!$A$11:$A$45,"*M") -> 35 | F20: =IF(AND(B20=C20,D20=E20),"✔ Verificado","✖ Revisar") -> ✖ Revisar
A21: Toacaso | B21: =COUNTIF($A$26:$A$74,A21) -> 3 | C21: =COUNTIFS($A$26:$A$74,A21,$P$26:$P$74,"✔ Verificado") -> 0 | D21: =SUMIFS($G$26:$G$74,$A$26:$A$74,A21)+SUMIFS($I$26:$I$74,$A$26:$A$74,A21) -> 31 | E21: =COUNTIF(Toacaso!$A$11:$A$41,"*F")+COUNTIF(Toacaso!$A$11:$A$41,"*M") -> 31 | F21: =IF(AND(B21=C21,D21=E21),"✔ Verificado","✖ Revisar") -> ✖ Revisar
A22: TOTAL LATACUNGA | B22: =SUM(B7:B21) -> 49 | C22: =SUM(C7:C21) -> 0 | D22: =SUM(D7:D21) -> 492 | E22: =SUM(E7:E21) -> 492 | F22: =IF(AND(B22=C22,D22=E22),"✔ Verificado","✖ Revisar") -> ✖ Revisar
A24: DETALLE POR RECINTO
A25: Parroquia (hoja) | B25: Zona | C25: Código recinto | D25: Recinto electoral | E25: Electores CNE | F25: Electores matriz | G25: Juntas F CNE | H25: Juntas F matriz | I25: Juntas M CNE | J25: Juntas M matriz | K25: JRV F CNE | L25: JRV F matriz | M25: JRV M CNE | N25: JRV M matriz | O25: Juntas totales CNE | P25: Estado
A26: Eloy Alfaro (San Felipe) | B26: — | C26: 1560 | D26: ESC. DE EDUCACION BASICA CLUB ROTARIO | E26: 4200 | F26: =SUMIFS('Eloy Alfaro (San Felipe)'!$E$5:$E$11,'Eloy Alfaro (San Felipe)'!$B$5:$B$11,D26) -> 4200 | G26: 7 | H26: =COUNTIFS('Eloy Alfaro (San Felipe)'!$B$15:$B$105,D26,'Eloy Alfaro (San Felipe)'!$A$15:$A$105,"*F") -> 7 | I26: 5 | J26: =COUNTIFS('Eloy Alfaro (San Felipe)'!$B$15:$B$105,D26,'Eloy Alfaro (San Felipe)'!$A$15:$A$105,"*M") -> 5 | K26: 1F – 7F | L26: =IFERROR(IF(H26=0,"—",(1000-SUMPRODUCT(MAX(('Eloy Alfaro (San Felipe)'!$B$15:$B$105=D26)*(RIGHT('Eloy Alfaro (San Felipe)'!$A$15:$A$105,1)="F")*(1000-VALUE("0"&SUBSTITUTE(SUBSTITUTE(UPPER('Eloy Alfaro (San Felipe)'!$A$15:$A$105),"F",""),"M",""))))))&"F – "&SUMPRODUCT(MAX(('Eloy Alfaro (San Felipe)'!$B$15:$B$105=D26)*(RIGHT('Eloy Alfaro (San Felipe)'!$A$15:$A$105,1)="F")*VALUE("0"&SUBSTITUTE(SUBSTITUTE(UPPER('Eloy Alfaro (San Felipe)'!$A$15:$A$105),"F",""),"M",""))))&"F"),"✖ error") -> 1000F – 0F | M26: 1M – 5M | N26: =IFERROR(IF(J26=0,"—",(1000-SUMPRODUCT(MAX(('Eloy Alfaro (San Felipe)'!$B$15:$B$105=D26)*(RIGHT('Eloy Alfaro (San Felipe)'!$A$15:$A$105,1)="M")*(1000-VALUE("0"&SUBSTITUTE(SUBSTITUTE(UPPER('Eloy Alfaro (San Felipe)'!$A$15:$A$105),"F",""),"M",""))))))&"M – "&SUMPRODUCT(MAX(('Eloy Alfaro (San Felipe)'!$B$15:$B$105=D26)*(RIGHT('Eloy Alfaro (San Felipe)'!$A$15:$A$105,1)="M")*VALUE("0"&SUBSTITUTE(SUBSTITUTE(UPPER('Eloy Alfaro (San Felipe)'!$A$15:$A$105),"F",""),"M",""))))&"M"),"✖ error") -> 5M – 5M | O26: 12 | P26: =IFERROR(IF(AND(E26=F26,G26=H26,I26=J26,K26=L26,M26=N26,SUMPRODUCT(('Eloy Alfaro (San Felipe)'!$B$15:$B$105=D26)*(RIGHT('Eloy Alfaro (San Felipe)'!$A$15:$A$105,1)="F"))=7,SUMPRODUCT(('Eloy Alfaro (San Felipe)'!$B$15:$B$105=D26)*(RIGHT('Eloy Alfaro (San Felipe)'!$A$15:$A$105,1)="F")*VALUE("0"&SUBSTITUTE(SUBSTITUTE(UPPER('Eloy Alfaro (San Felipe)'!$A$15:$A$105),"F",""),"M","")))=28,SUMPRODUCT(('Eloy Alfaro (San Felipe)'!$B$15:$B$105=D26)*(RIGHT('Eloy Alfaro (San Felipe)'!$A$15:$A$105,1)="F")*VALUE("0"&SUBSTITUTE(SUBSTITUTE(UPPER('Eloy Alfaro (San Felipe)'!$A$15:$A$105),"F",""),"M",""))^2)=140,SUMPRODUCT(('Eloy Alfaro (San Felipe)'!$B$15:$B$105=D26)*(RIGHT('Eloy Alfaro (San Felipe)'!$A$15:$A$105,1)="M"))=5,SUMPRODUCT(('Eloy Alfaro (San Felipe)'!$B$15:$B$105=D26)*(RIGHT('Eloy Alfaro (San Felipe)'!$A$15:$A$105,1)="M")*VALUE("0"&SUBSTITUTE(SUBSTITUTE(UPPER('Eloy Alfaro (San Felipe)'!$A$15:$A$105),"F",""),"M","")))=15,SUMPRODUCT(('Eloy Alfaro (San Felipe)'!$B$15:$B$105=D26)*(RIGHT('Eloy Alfaro (San Felipe)'!$A$15:$A$105,1)="M")*VALUE("0"&SUBSTITUTE(SUBSTITUTE(UPPER('Eloy Alfaro (San Felipe)'!$A$15:$A$105),"F",""),"M",""))^2)=55),"✔ Verificado","✖ Revisar"),"✖ Revisar") -> ✖ Revisar
A27: Eloy Alfaro (San Felipe) | B27: — | C27: 324 | D27: U.E. JORGE ICAZA | E27: 4200 | F27: =SUMIFS('Eloy Alfaro (San Felipe)'!$E$5:$E$11,'Eloy Alfaro (San Felipe)'!$B$5:$B$11,D27) -> 4200 | G27: 6 | H27: =COUNTIFS('Eloy Alfaro (San Felipe)'!$B$15:$B$105,D27,'Eloy Alfaro (San Felipe)'!$A$15:$A$105,"*F") -> 6 | I27: 6 | J27: =COUNTIFS('Eloy Alfaro (San Felipe)'!$B$15:$B$105,D27,'Eloy Alfaro (San Felipe)'!$A$15:$A$105,"*M") -> 6 | K27: 8F – 13F | L27: =IFERROR(IF(H27=0,"—",(1000-SUMPRODUCT(MAX(('Eloy Alfaro (San Felipe)'!$B$15:$B$105=D27)*(RIGHT('Eloy Alfaro (San Felipe)'!$A$15:$A$105,1)="F")*(1000-VALUE("0"&SUBSTITUTE(SUBSTITUTE(UPPER('Eloy Alfaro (San Felipe)'!$A$15:$A$105),"F",""),"M",""))))))&"F – "&SUMPRODUCT(MAX(('Eloy Alfaro (San Felipe)'!$B$15:$B$105=D27)*(RIGHT('Eloy Alfaro (San Felipe)'!$A$15:$A$105,1)="F")*VALUE("0"&SUBSTITUTE(SUBSTITUTE(UPPER('Eloy Alfaro (San Felipe)'!$A$15:$A$105),"F",""),"M",""))))&"F"),"✖ error") -> 8F – 8F | M27: 6M – 11M | N27: =IFERROR(IF(J27=0,"—",(1000-SUMPRODUCT(MAX(('Eloy Alfaro (San Felipe)'!$B$15:$B$105=D27)*(RIGHT('Eloy Alfaro (San Felipe)'!$A$15:$A$105,1)="M")*(1000-VALUE("0"&SUBSTITUTE(SUBSTITUTE(UPPER('Eloy Alfaro (San Felipe)'!$A$15:$A$105),"F",""),"M",""))))))&"M – "&SUMPRODUCT(MAX(('Eloy Alfaro (San Felipe)'!$B$15:$B$105=D27)*(RIGHT('Eloy Alfaro (San Felipe)'!$A$15:$A$105,1)="M")*VALUE("0"&SUBSTITUTE(SUBSTITUTE(UPPER('Eloy Alfaro (San Felipe)'!$A$15:$A$105),"F",""),"M",""))))&"M"),"✖ error") -> 1000M – 0M | O27: 12 | P27: =IFERROR(IF(AND(E27=F27,G27=H27,I27=J27,K27=L27,M27=N27,SUMPRODUCT(('Eloy Alfaro (San Felipe)'!$B$15:$B$105=D27)*(RIGHT('Eloy Alfaro (San Felipe)'!$A$15:$A$105,1)="F"))=6,SUMPRODUCT(('Eloy Alfaro (San Felipe)'!$B$15:$B$105=D27)*(RIGHT('Eloy Alfaro (San Felipe)'!$A$15:$A$105,1)="F")*VALUE("0"&SUBSTITUTE(SUBSTITUTE(UPPER('Eloy Alfaro (San Felipe)'!$A$15:$A$105),"F",""),"M","")))=63,SUMPRODUCT(('Eloy Alfaro (San Felipe)'!$B$15:$B$105=D27)*(RIGHT('Eloy Alfaro (San Felipe)'!$A$15:$A$105,1)="F")*VALUE("0"&SUBSTITUTE(SUBSTITUTE(UPPER('Eloy Alfaro (San Felipe)'!$A$15:$A$105),"F",""),"M",""))^2)=679,SUMPRODUCT(('Eloy Alfaro (San Felipe)'!$B$15:$B$105=D27)*(RIGHT('Eloy Alfaro (San Felipe)'!$A$15:$A$105,1)="M"))=6,SUMPRODUCT(('Eloy Alfaro (San Felipe)'!$B$15:$B$105=D27)*(RIGHT('Eloy Alfaro (San Felipe)'!$A$15:$A$105,1)="M")*VALUE("0"&SUBSTITUTE(SUBSTITUTE(UPPER('Eloy Alfaro (San Felipe)'!$A$15:$A$105),"F",""),"M","")))=51,SUMPRODUCT(('Eloy Alfaro (San Felipe)'!$B$15:$B$105=D27)*(RIGHT('Eloy Alfaro (San Felipe)'!$A$15:$A$105,1)="M")*VALUE("0"&SUBSTITUTE(SUBSTITUTE(UPPER('Eloy Alfaro (San Felipe)'!$A$15:$A$105),"F",""),"M",""))^2)=451),"✔ Verificado","✖ Revisar"),"✖ Revisar") -> ✖ Revisar
A28: Eloy Alfaro (San Felipe) | B28: — | C28: 6331 | D28: U.E. JUAN ABEL ECHEVERRIA | E28: 4550 | F28: =SUMIFS('Eloy Alfaro (San Felipe)'!$E$5:$E$11,'Eloy Alfaro (San Felipe)'!$B$5:$B$11,D28) -> 4550 | G28: 7 | H28: =COUNTIFS('Eloy Alfaro (San Felipe)'!$B$15:$B$105,D28,'Eloy Alfaro (San Felipe)'!$A$15:$A$105,"*F") -> 7 | I28: 6 | J28: =COUNTIFS('Eloy Alfaro (San Felipe)'!$B$15:$B$105,D28,'Eloy Alfaro (San Felipe)'!$A$15:$A$105,"*M") -> 6 | K28: 14F – 20F | L28: =IFERROR(IF(H28=0,"—",(1000-SUMPRODUCT(MAX(('Eloy Alfaro (San Felipe)'!$B$15:$B$105=D28)*(RIGHT('Eloy Alfaro (San Felipe)'!$A$15:$A$105,1)="F")*(1000-VALUE("0"&SUBSTITUTE(SUBSTITUTE(UPPER('Eloy Alfaro (San Felipe)'!$A$15:$A$105),"F",""),"M",""))))))&"F – "&SUMPRODUCT(MAX(('Eloy Alfaro (San Felipe)'!$B$15:$B$105=D28)*(RIGHT('Eloy Alfaro (San Felipe)'!$A$15:$A$105,1)="F")*VALUE("0"&SUBSTITUTE(SUBSTITUTE(UPPER('Eloy Alfaro (San Felipe)'!$A$15:$A$105),"F",""),"M",""))))&"F"),"✖ error") -> 9F – 9F | M28: 12M – 17M | N28: =IFERROR(IF(J28=0,"—",(1000-SUMPRODUCT(MAX(('Eloy Alfaro (San Felipe)'!$B$15:$B$105=D28)*(RIGHT('Eloy Alfaro (San Felipe)'!$A$15:$A$105,1)="M")*(1000-VALUE("0"&SUBSTITUTE(SUBSTITUTE(UPPER('Eloy Alfaro (San Felipe)'!$A$15:$A$105),"F",""),"M",""))))))&"M – "&SUMPRODUCT(MAX(('Eloy Alfaro (San Felipe)'!$B$15:$B$105=D28)*(RIGHT('Eloy Alfaro (San Felipe)'!$A$15:$A$105,1)="M")*VALUE("0"&SUBSTITUTE(SUBSTITUTE(UPPER('Eloy Alfaro (San Felipe)'!$A$15:$A$105),"F",""),"M",""))))&"M"),"✖ error") -> 1000M – 0M | O28: 13 | P28: =IFERROR(IF(AND(E28=F28,G28=H28,I28=J28,K28=L28,M28=N28,SUMPRODUCT(('Eloy Alfaro (San Felipe)'!$B$15:$B$105=D28)*(RIGHT('Eloy Alfaro (San Felipe)'!$A$15:$A$105,1)="F"))=7,SUMPRODUCT(('Eloy Alfaro (San Felipe)'!$B$15:$B$105=D28)*(RIGHT('Eloy Alfaro (San Felipe)'!$A$15:$A$105,1)="F")*VALUE("0"&SUBSTITUTE(SUBSTITUTE(UPPER('Eloy Alfaro (San Felipe)'!$A$15:$A$105),"F",""),"M","")))=119,SUMPRODUCT(('Eloy Alfaro (San Felipe)'!$B$15:$B$105=D28)*(RIGHT('Eloy Alfaro (San Felipe)'!$A$15:$A$105,1)="F")*VALUE("0"&SUBSTITUTE(SUBSTITUTE(UPPER('Eloy Alfaro (San Felipe)'!$A$15:$A$105),"F",""),"M",""))^2)=2051,SUMPRODUCT(('Eloy Alfaro (San Felipe)'!$B$15:$B$105=D28)*(RIGHT('Eloy Alfaro (San Felipe)'!$A$15:$A$105,1)="M"))=6,SUMPRODUCT(('Eloy Alfaro (San Felipe)'!$B$15:$B$105=D28)*(RIGHT('Eloy Alfaro (San Felipe)'!$A$15:$A$105,1)="M")*VALUE("0"&SUBSTITUTE(SUBSTITUTE(UPPER('Eloy Alfaro (San Felipe)'!$A$15:$A$105),"F",""),"M","")))=87,SUMPRODUCT(('Eloy Alfaro (San Felipe)'!$B$15:$B$105=D28)*(RIGHT('Eloy Alfaro (San Felipe)'!$A$15:$A$105,1)="M")*VALUE("0"&SUBSTITUTE(SUBSTITUTE(UPPER('Eloy Alfaro (San Felipe)'!$A$15:$A$105),"F",""),"M",""))^2)=1279),"✔ Verificado","✖ Revisar"),"✖ Revisar") -> ✖ Revisar
A29: Eloy Alfaro (San Felipe) | B29: — | C29: 406 | D29: U. E. LIC. JAIME ANDRADE FABARA | E29: 4200 | F29: =SUMIFS('Eloy Alfaro (San Felipe)'!$E$5:$E$11,'Eloy Alfaro (San Felipe)'!$B$5:$B$11,D29) -> 4200 | G29: 6 | H29: =COUNTIFS('Eloy Alfaro (San Felipe)'!$B$15:$B$105,D29,'Eloy Alfaro (San Felipe)'!$A$15:$A$105,"*F") -> 6 | I29: 6 | J29: =COUNTIFS('Eloy Alfaro (San Felipe)'!$B$15:$B$105,D29,'Eloy Alfaro (San Felipe)'!$A$15:$A$105,"*M") -> 6 | K29: 21F – 26F | L29: =IFERROR(IF(H29=0,"—",(1000-SUMPRODUCT(MAX(('Eloy Alfaro (San Felipe)'!$B$15:$B$105=D29)*(RIGHT('Eloy Alfaro (San Felipe)'!$A$15:$A$105,1)="F")*(1000-VALUE("0"&SUBSTITUTE(SUBSTITUTE(UPPER('Eloy Alfaro (San Felipe)'!$A$15:$A$105),"F",""),"M",""))))))&"F – "&SUMPRODUCT(MAX(('Eloy Alfaro (San Felipe)'!$B$15:$B$105=D29)*(RIGHT('Eloy Alfaro (San Felipe)'!$A$15:$A$105,1)="F")*VALUE("0"&SUBSTITUTE(SUBSTITUTE(UPPER('Eloy Alfaro (San Felipe)'!$A$15:$A$105),"F",""),"M",""))))&"F"),"✖ error") -> 10F – 10F | M29: 18M – 23M | N29: =IFERROR(IF(J29=0,"—",(1000-SUMPRODUCT(MAX(('Eloy Alfaro (San Felipe)'!$B$15:$B$105=D29)*(RIGHT('Eloy Alfaro (San Felipe)'!$A$15:$A$105,1)="M")*(1000-VALUE("0"&SUBSTITUTE(SUBSTITUTE(UPPER('Eloy Alfaro (San Felipe)'!$A$15:$A$105),"F",""),"M",""))))))&"M – "&SUMPRODUCT(MAX(('Eloy Alfaro (San Felipe)'!$B$15:$B$105=D29)*(RIGHT('Eloy Alfaro (San Felipe)'!$A$15:$A$105,1)="M")*VALUE("0"&SUBSTITUTE(SUBSTITUTE(UPPER('Eloy Alfaro (San Felipe)'!$A$15:$A$105),"F",""),"M",""))))&"M"),"✖ error") -> 1000M – 0M | O29: 12 | P29: =IFERROR(IF(AND(E29=F29,G29=H29,I29=J29,K29=L29,M29=N29,SUMPRODUCT(('Eloy Alfaro (San Felipe)'!$B$15:$B$105=D29)*(RIGHT('Eloy Alfaro (San Felipe)'!$A$15:$A$105,1)="F"))=6,SUMPRODUCT(('Eloy Alfaro (San Felipe)'!$B$15:$B$105=D29)*(RIGHT('Eloy Alfaro (San Felipe)'!$A$15:$A$105,1)="F")*VALUE("0"&SUBSTITUTE(SUBSTITUTE(UPPER('Eloy Alfaro (San Felipe)'!$A$15:$A$105),"F",""),"M","")))=141,SUMPRODUCT(('Eloy Alfaro (San Felipe)'!$B$15:$B$105=D29)*(RIGHT('Eloy Alfaro (San Felipe)'!$A$15:$A$105,1)="F")*VALUE("0"&SUBSTITUTE(SUBSTITUTE(UPPER('Eloy Alfaro (San Felipe)'!$A$15:$A$105),"F",""),"M",""))^2)=3331,SUMPRODUCT(('Eloy Alfaro (San Felipe)'!$B$15:$B$105=D29)*(RIGHT('Eloy Alfaro (San Felipe)'!$A$15:$A$105,1)="M"))=6,SUMPRODUCT(('Eloy Alfaro (San Felipe)'!$B$15:$B$105=D29)*(RIGHT('Eloy Alfaro (San Felipe)'!$A$15:$A$105,1)="M")*VALUE("0"&SUBSTITUTE(SUBSTITUTE(UPPER('Eloy Alfaro (San Felipe)'!$A$15:$A$105),"F",""),"M","")))=123,SUMPRODUCT(('Eloy Alfaro (San Felipe)'!$B$15:$B$105=D29)*(RIGHT('Eloy Alfaro (San Felipe)'!$A$15:$A$105,1)="M")*VALUE("0"&SUBSTITUTE(SUBSTITUTE(UPPER('Eloy Alfaro (San Felipe)'!$A$15:$A$105),"F",""),"M",""))^2)=2539),"✔ Verificado","✖ Revisar"),"✖ Revisar") -> ✖ Revisar
A30: Eloy Alfaro (San Felipe) | B30: — | C30: 8015 | D30: U.E. MONSEÑOR LEONIDAS PROAÑO/LATACUNGA | E30: 2800 | F30: =SUMIFS('Eloy Alfaro (San Felipe)'!$E$5:$E$11,'Eloy Alfaro (San Felipe)'!$B$5:$B$11,D30) -> 2800 | G30: 4 | H30: =COUNTIFS('Eloy Alfaro (San Felipe)'!$B$15:$B$105,D30,'Eloy Alfaro (San Felipe)'!$A$15:$A$105,"*F") -> 4 | I30: 4 | J30: =COUNTIFS('Eloy Alfaro (San Felipe)'!$B$15:$B$105,D30,'Eloy Alfaro (San Felipe)'!$A$15:$A$105,"*M") -> 4 | K30: 27F – 30F | L30: =IFERROR(IF(H30=0,"—",(1000-SUMPRODUCT(MAX(('Eloy Alfaro (San Felipe)'!$B$15:$B$105=D30)*(RIGHT('Eloy Alfaro (San Felipe)'!$A$15:$A$105,1)="F")*(1000-VALUE("0"&SUBSTITUTE(SUBSTITUTE(UPPER('Eloy Alfaro (San Felipe)'!$A$15:$A$105),"F",""),"M",""))))))&"F – "&SUMPRODUCT(MAX(('Eloy Alfaro (San Felipe)'!$B$15:$B$105=D30)*(RIGHT('Eloy Alfaro (San Felipe)'!$A$15:$A$105,1)="F")*VALUE("0"&SUBSTITUTE(SUBSTITUTE(UPPER('Eloy Alfaro (San Felipe)'!$A$15:$A$105),"F",""),"M",""))))&"F"),"✖ error") -> 11F – 11F | M30: 24M – 27M | N30: =IFERROR(IF(J30=0,"—",(1000-SUMPRODUCT(MAX(('Eloy Alfaro (San Felipe)'!$B$15:$B$105=D30)*(RIGHT('Eloy Alfaro (San Felipe)'!$A$15:$A$105,1)="M")*(1000-VALUE("0"&SUBSTITUTE(SUBSTITUTE(UPPER('Eloy Alfaro (San Felipe)'!$A$15:$A$105),"F",""),"M",""))))))&"M – "&SUMPRODUCT(MAX(('Eloy Alfaro (San Felipe)'!$B$15:$B$105=D30)*(RIGHT('Eloy Alfaro (San Felipe)'!$A$15:$A$105,1)="M")*VALUE("0"&SUBSTITUTE(SUBSTITUTE(UPPER('Eloy Alfaro (San Felipe)'!$A$15:$A$105),"F",""),"M",""))))&"M"),"✖ error") -> 1000M – 0M | O30: 8 | P30: =IFERROR(IF(AND(E30=F30,G30=H30,I30=J30,K30=L30,M30=N30,SUMPRODUCT(('Eloy Alfaro (San Felipe)'!$B$15:$B$105=D30)*(RIGHT('Eloy Alfaro (San Felipe)'!$A$15:$A$105,1)="F"))=4,SUMPRODUCT(('Eloy Alfaro (San Felipe)'!$B$15:$B$105=D30)*(RIGHT('Eloy Alfaro (San Felipe)'!$A$15:$A$105,1)="F")*VALUE("0"&SUBSTITUTE(SUBSTITUTE(UPPER('Eloy Alfaro (San Felipe)'!$A$15:$A$105),"F",""),"M","")))=114,SUMPRODUCT(('Eloy Alfaro (San Felipe)'!$B$15:$B$105=D30)*(RIGHT('Eloy Alfaro (San Felipe)'!$A$15:$A$105,1)="F")*VALUE("0"&SUBSTITUTE(SUBSTITUTE(UPPER('Eloy Alfaro (San Felipe)'!$A$15:$A$105),"F",""),"M",""))^2)=3254,SUMPRODUCT(('Eloy Alfaro (San Felipe)'!$B$15:$B$105=D30)*(RIGHT('Eloy Alfaro (San Felipe)'!$A$15:$A$105,1)="M"))=4,SUMPRODUCT(('Eloy Alfaro (San Felipe)'!$B$15:$B$105=D30)*(RIGHT('Eloy Alfaro (San Felipe)'!$A$15:$A$105,1)="M")*VALUE("0"&SUBSTITUTE(SUBSTITUTE(UPPER('Eloy Alfaro (San Felipe)'!$A$15:$A$105),"F",""),"M","")))=102,SUMPRODUCT(('Eloy Alfaro (San Felipe)'!$B$15:$B$105=D30)*(RIGHT('Eloy Alfaro (San Felipe)'!$A$15:$A$105,1)="M")*VALUE("0"&SUBSTITUTE(SUBSTITUTE(UPPER('Eloy Alfaro (San Felipe)'!$A$15:$A$105),"F",""),"M",""))^2)=2606),"✔ Verificado","✖ Revisar"),"✖ Revisar") -> ✖ Revisar
A31: Eloy Alfaro (San Felipe) | B31: — | C31: 366 | D31: U.E. ANA PAEZ MANUEL SALCEDO/ ESCUELA MANUEL SALCEDO | E31: 3500 | F31: =SUMIFS('Eloy Alfaro (San Felipe)'!$E$5:$E$11,'Eloy Alfaro (San Felipe)'!$B$5:$B$11,D31) -> 3500 | G31: 5 | H31: =COUNTIFS('Eloy Alfaro (San Felipe)'!$B$15:$B$105,D31,'Eloy Alfaro (San Felipe)'!$A$15:$A$105,"*F") -> 5 | I31: 5 | J31: =COUNTIFS('Eloy Alfaro (San Felipe)'!$B$15:$B$105,D31,'Eloy Alfaro (San Felipe)'!$A$15:$A$105,"*M") -> 5 | K31: 31F – 35F | L31: =IFERROR(IF(H31=0,"—",(1000-SUMPRODUCT(MAX(('Eloy Alfaro (San Felipe)'!$B$15:$B$105=D31)*(RIGHT('Eloy Alfaro (San Felipe)'!$A$15:$A$105,1)="F")*(1000-VALUE("0"&SUBSTITUTE(SUBSTITUTE(UPPER('Eloy Alfaro (San Felipe)'!$A$15:$A$105),"F",""),"M",""))))))&"F – "&SUMPRODUCT(MAX(('Eloy Alfaro (San Felipe)'!$B$15:$B$105=D31)*(RIGHT('Eloy Alfaro (San Felipe)'!$A$15:$A$105,1)="F")*VALUE("0"&SUBSTITUTE(SUBSTITUTE(UPPER('Eloy Alfaro (San Felipe)'!$A$15:$A$105),"F",""),"M",""))))&"F"),"✖ error") -> 12F – 12F | M31: 28M – 32M | N31: =IFERROR(IF(J31=0,"—",(1000-SUMPRODUCT(MAX(('Eloy Alfaro (San Felipe)'!$B$15:$B$105=D31)*(RIGHT('Eloy Alfaro (San Felipe)'!$A$15:$A$105,1)="M")*(1000-VALUE("0"&SUBSTITUTE(SUBSTITUTE(UPPER('Eloy Alfaro (San Felipe)'!$A$15:$A$105),"F",""),"M",""))))))&"M – "&SUMPRODUCT(MAX(('Eloy Alfaro (San Felipe)'!$B$15:$B$105=D31)*(RIGHT('Eloy Alfaro (San Felipe)'!$A$15:$A$105,1)="M")*VALUE("0"&SUBSTITUTE(SUBSTITUTE(UPPER('Eloy Alfaro (San Felipe)'!$A$15:$A$105),"F",""),"M",""))))&"M"),"✖ error") -> 1000M – 0M | O31: 10 | P31: =IFERROR(IF(AND(E31=F31,G31=H31,I31=J31,K31=L31,M31=N31,SUMPRODUCT(('Eloy Alfaro (San Felipe)'!$B$15:$B$105=D31)*(RIGHT('Eloy Alfaro (San Felipe)'!$A$15:$A$105,1)="F"))=5,SUMPRODUCT(('Eloy Alfaro (San Felipe)'!$B$15:$B$105=D31)*(RIGHT('Eloy Alfaro (San Felipe)'!$A$15:$A$105,1)="F")*VALUE("0"&SUBSTITUTE(SUBSTITUTE(UPPER('Eloy Alfaro (San Felipe)'!$A$15:$A$105),"F",""),"M","")))=165,SUMPRODUCT(('Eloy Alfaro (San Felipe)'!$B$15:$B$105=D31)*(RIGHT('Eloy Alfaro (San Felipe)'!$A$15:$A$105,1)="F")*VALUE("0"&SUBSTITUTE(SUBSTITUTE(UPPER('Eloy Alfaro (San Felipe)'!$A$15:$A$105),"F",""),"M",""))^2)=5455,SUMPRODUCT(('Eloy Alfaro (San Felipe)'!$B$15:$B$105=D31)*(RIGHT('Eloy Alfaro (San Felipe)'!$A$15:$A$105,1)="M"))=5,SUMPRODUCT(('Eloy Alfaro (San Felipe)'!$B$15:$B$105=D31)*(RIGHT('Eloy Alfaro (San Felipe)'!$A$15:$A$105,1)="M")*VALUE("0"&SUBSTITUTE(SUBSTITUTE(UPPER('Eloy Alfaro (San Felipe)'!$A$15:$A$105),"F",""),"M","")))=150,SUMPRODUCT(('Eloy Alfaro (San Felipe)'!$B$15:$B$105=D31)*(RIGHT('Eloy Alfaro (San Felipe)'!$A$15:$A$105,1)="M")*VALUE("0"&SUBSTITUTE(SUBSTITUTE(UPPER('Eloy Alfaro (San Felipe)'!$A$15:$A$105),"F",""),"M",""))^2)=4510),"✔ Verificado","✖ Revisar"),"✖ Revisar") -> ✖ Revisar
A32: Eloy Alfaro (San Felipe) | B32: — | C32: 354 | D32: U.E. ANA PAEZ MANUEL SALCEDO/ ESCUELA ANA PAEZ | E32: 8123 | F32: =SUMIFS('Eloy Alfaro (San Felipe)'!$E$5:$E$11,'Eloy Alfaro (San Felipe)'!$B$5:$B$11,D32) -> 8123 | G32: 12 | H32: =COUNTIFS('Eloy Alfaro (San Felipe)'!$B$15:$B$105,D32,'Eloy Alfaro (San Felipe)'!$A$15:$A$105,"*F") -> 12 | I32: 12 | J32: =COUNTIFS('Eloy Alfaro (San Felipe)'!$B$15:$B$105,D32,'Eloy Alfaro (San Felipe)'!$A$15:$A$105,"*M") -> 12 | K32: 36F – 47F | L32: =IFERROR(IF(H32=0,"—",(1000-SUMPRODUCT(MAX(('Eloy Alfaro (San Felipe)'!$B$15:$B$105=D32)*(RIGHT('Eloy Alfaro (San Felipe)'!$A$15:$A$105,1)="F")*(1000-VALUE("0"&SUBSTITUTE(SUBSTITUTE(UPPER('Eloy Alfaro (San Felipe)'!$A$15:$A$105),"F",""),"M",""))))))&"F – "&SUMPRODUCT(MAX(('Eloy Alfaro (San Felipe)'!$B$15:$B$105=D32)*(RIGHT('Eloy Alfaro (San Felipe)'!$A$15:$A$105,1)="F")*VALUE("0"&SUBSTITUTE(SUBSTITUTE(UPPER('Eloy Alfaro (San Felipe)'!$A$15:$A$105),"F",""),"M",""))))&"F"),"✖ error") -> 13F – 13F | M32: 33M – 44M | N32: =IFERROR(IF(J32=0,"—",(1000-SUMPRODUCT(MAX(('Eloy Alfaro (San Felipe)'!$B$15:$B$105=D32)*(RIGHT('Eloy Alfaro (San Felipe)'!$A$15:$A$105,1)="M")*(1000-VALUE("0"&SUBSTITUTE(SUBSTITUTE(UPPER('Eloy Alfaro (San Felipe)'!$A$15:$A$105),"F",""),"M",""))))))&"M – "&SUMPRODUCT(MAX(('Eloy Alfaro (San Felipe)'!$B$15:$B$105=D32)*(RIGHT('Eloy Alfaro (San Felipe)'!$A$15:$A$105,1)="M")*VALUE("0"&SUBSTITUTE(SUBSTITUTE(UPPER('Eloy Alfaro (San Felipe)'!$A$15:$A$105),"F",""),"M",""))))&"M"),"✖ error") -> 1000M – 0M | O32: 24 | P32: =IFERROR(IF(AND(E32=F32,G32=H32,I32=J32,K32=L32,M32=N32,SUMPRODUCT(('Eloy Alfaro (San Felipe)'!$B$15:$B$105=D32)*(RIGHT('Eloy Alfaro (San Felipe)'!$A$15:$A$105,1)="F"))=12,SUMPRODUCT(('Eloy Alfaro (San Felipe)'!$B$15:$B$105=D32)*(RIGHT('Eloy Alfaro (San Felipe)'!$A$15:$A$105,1)="F")*VALUE("0"&SUBSTITUTE(SUBSTITUTE(UPPER('Eloy Alfaro (San Felipe)'!$A$15:$A$105),"F",""),"M","")))=498,SUMPRODUCT(('Eloy Alfaro (San Felipe)'!$B$15:$B$105=D32)*(RIGHT('Eloy Alfaro (San Felipe)'!$A$15:$A$105,1)="F")*VALUE("0"&SUBSTITUTE(SUBSTITUTE(UPPER('Eloy Alfaro (San Felipe)'!$A$15:$A$105),"F",""),"M",""))^2)=20810,SUMPRODUCT(('Eloy Alfaro (San Felipe)'!$B$15:$B$105=D32)*(RIGHT('Eloy Alfaro (San Felipe)'!$A$15:$A$105,1)="M"))=12,SUMPRODUCT(('Eloy Alfaro (San Felipe)'!$B$15:$B$105=D32)*(RIGHT('Eloy Alfaro (San Felipe)'!$A$15:$A$105,1)="M")*VALUE("0"&SUBSTITUTE(SUBSTITUTE(UPPER('Eloy Alfaro (San Felipe)'!$A$15:$A$105),"F",""),"M","")))=462,SUMPRODUCT(('Eloy Alfaro (San Felipe)'!$B$15:$B$105=D32)*(RIGHT('Eloy Alfaro (San Felipe)'!$A$15:$A$105,1)="M")*VALUE("0"&SUBSTITUTE(SUBSTITUTE(UPPER('Eloy Alfaro (San Felipe)'!$A$15:$A$105),"F",""),"M",""))^2)=17930),"✔ Verificado","✖ Revisar"),"✖ Revisar") -> ✖ Revisar
A33: Ignacio Flores | B33: IGNACIO FLORES | C33: 1576 | D33: U.E. LUIS FERNANDO RUIZ | E33: 5600 | F33: =SUMIFS('Ignacio Flores'!$E$5:$E$9,'Ignacio Flores'!$B$5:$B$9,D33) -> 5600 | G33: 9 | H33: =COUNTIFS('Ignacio Flores'!$B$13:$B$67,D33,'Ignacio Flores'!$A$13:$A$67,"*F") -> 9 | I33: 7 | J33: =COUNTIFS('Ignacio Flores'!$B$13:$B$67,D33,'Ignacio Flores'!$A$13:$A$67,"*M") -> 7 | K33: 1F – 9F | L33: =IFERROR(IF(H33=0,"—",(1000-SUMPRODUCT(MAX(('Ignacio Flores'!$B$13:$B$67=D33)*(RIGHT('Ignacio Flores'!$A$13:$A$67,1)="F")*(1000-VALUE("0"&SUBSTITUTE(SUBSTITUTE(UPPER('Ignacio Flores'!$A$13:$A$67),"F",""),"M",""))))))&"F – "&SUMPRODUCT(MAX(('Ignacio Flores'!$B$13:$B$67=D33)*(RIGHT('Ignacio Flores'!$A$13:$A$67,1)="F")*VALUE("0"&SUBSTITUTE(SUBSTITUTE(UPPER('Ignacio Flores'!$A$13:$A$67),"F",""),"M",""))))&"F"),"✖ error") -> 14F – 14F | M33: 1M – 7M | N33: =IFERROR(IF(J33=0,"—",(1000-SUMPRODUCT(MAX(('Ignacio Flores'!$B$13:$B$67=D33)*(RIGHT('Ignacio Flores'!$A$13:$A$67,1)="M")*(1000-VALUE("0"&SUBSTITUTE(SUBSTITUTE(UPPER('Ignacio Flores'!$A$13:$A$67),"F",""),"M",""))))))&"M – "&SUMPRODUCT(MAX(('Ignacio Flores'!$B$13:$B$67=D33)*(RIGHT('Ignacio Flores'!$A$13:$A$67,1)="M")*VALUE("0"&SUBSTITUTE(SUBSTITUTE(UPPER('Ignacio Flores'!$A$13:$A$67),"F",""),"M",""))))&"M"),"✖ error") -> 1000M – 0M | O33: 16 | P33: =IFERROR(IF(AND(E33=F33,G33=H33,I33=J33,K33=L33,M33=N33,SUMPRODUCT(('Ignacio Flores'!$B$13:$B$67=D33)*(RIGHT('Ignacio Flores'!$A$13:$A$67,1)="F"))=9,SUMPRODUCT(('Ignacio Flores'!$B$13:$B$67=D33)*(RIGHT('Ignacio Flores'!$A$13:$A$67,1)="F")*VALUE("0"&SUBSTITUTE(SUBSTITUTE(UPPER('Ignacio Flores'!$A$13:$A$67),"F",""),"M","")))=45,SUMPRODUCT(('Ignacio Flores'!$B$13:$B$67=D33)*(RIGHT('Ignacio Flores'!$A$13:$A$67,1)="F")*VALUE("0"&SUBSTITUTE(SUBSTITUTE(UPPER('Ignacio Flores'!$A$13:$A$67),"F",""),"M",""))^2)=285,SUMPRODUCT(('Ignacio Flores'!$B$13:$B$67=D33)*(RIGHT('Ignacio Flores'!$A$13:$A$67,1)="M"))=7,SUMPRODUCT(('Ignacio Flores'!$B$13:$B$67=D33)*(RIGHT('Ignacio Flores'!$A$13:$A$67,1)="M")*VALUE("0"&SUBSTITUTE(SUBSTITUTE(UPPER('Ignacio Flores'!$A$13:$A$67),"F",""),"M","")))=28,SUMPRODUCT(('Ignacio Flores'!$B$13:$B$67=D33)*(RIGHT('Ignacio Flores'!$A$13:$A$67,1)="M")*VALUE("0"&SUBSTITUTE(SUBSTITUTE(UPPER('Ignacio Flores'!$A$13:$A$67),"F",""),"M",""))^2)=140),"✔ Verificado","✖ Revisar"),"✖ Revisar") -> ✖ Revisar
A34: Ignacio Flores | B34: IGNACIO FLORES | C34: 1575 | D34: U.E. 11 DE NOVIEMBRE | E34: 4900 | F34: =SUMIFS('Ignacio Flores'!$E$5:$E$9,'Ignacio Flores'!$B$5:$B$9,D34) -> 4900 | G34: 7 | H34: =COUNTIFS('Ignacio Flores'!$B$13:$B$67,D34,'Ignacio Flores'!$A$13:$A$67,"*F") -> 7 | I34: 7 | J34: =COUNTIFS('Ignacio Flores'!$B$13:$B$67,D34,'Ignacio Flores'!$A$13:$A$67,"*M") -> 7 | K34: 10F – 16F | L34: =IFERROR(IF(H34=0,"—",(1000-SUMPRODUCT(MAX(('Ignacio Flores'!$B$13:$B$67=D34)*(RIGHT('Ignacio Flores'!$A$13:$A$67,1)="F")*(1000-VALUE("0"&SUBSTITUTE(SUBSTITUTE(UPPER('Ignacio Flores'!$A$13:$A$67),"F",""),"M",""))))))&"F – "&SUMPRODUCT(MAX(('Ignacio Flores'!$B$13:$B$67=D34)*(RIGHT('Ignacio Flores'!$A$13:$A$67,1)="F")*VALUE("0"&SUBSTITUTE(SUBSTITUTE(UPPER('Ignacio Flores'!$A$13:$A$67),"F",""),"M",""))))&"F"),"✖ error") -> 15F – 15F | M34: 8M – 14M | N34: =IFERROR(IF(J34=0,"—",(1000-SUMPRODUCT(MAX(('Ignacio Flores'!$B$13:$B$67=D34)*(RIGHT('Ignacio Flores'!$A$13:$A$67,1)="M")*(1000-VALUE("0"&SUBSTITUTE(SUBSTITUTE(UPPER('Ignacio Flores'!$A$13:$A$67),"F",""),"M",""))))))&"M – "&SUMPRODUCT(MAX(('Ignacio Flores'!$B$13:$B$67=D34)*(RIGHT('Ignacio Flores'!$A$13:$A$67,1)="M")*VALUE("0"&SUBSTITUTE(SUBSTITUTE(UPPER('Ignacio Flores'!$A$13:$A$67),"F",""),"M",""))))&"M"),"✖ error") -> 1000M – 0M | O34: 14 | P34: =IFERROR(IF(AND(E34=F34,G34=H34,I34=J34,K34=L34,M34=N34,SUMPRODUCT(('Ignacio Flores'!$B$13:$B$67=D34)*(RIGHT('Ignacio Flores'!$A$13:$A$67,1)="F"))=7,SUMPRODUCT(('Ignacio Flores'!$B$13:$B$67=D34)*(RIGHT('Ignacio Flores'!$A$13:$A$67,1)="F")*VALUE("0"&SUBSTITUTE(SUBSTITUTE(UPPER('Ignacio Flores'!$A$13:$A$67),"F",""),"M","")))=91,SUMPRODUCT(('Ignacio Flores'!$B$13:$B$67=D34)*(RIGHT('Ignacio Flores'!$A$13:$A$67,1)="F")*VALUE("0"&SUBSTITUTE(SUBSTITUTE(UPPER('Ignacio Flores'!$A$13:$A$67),"F",""),"M",""))^2)=1211,SUMPRODUCT(('Ignacio Flores'!$B$13:$B$67=D34)*(RIGHT('Ignacio Flores'!$A$13:$A$67,1)="M"))=7,SUMPRODUCT(('Ignacio Flores'!$B$13:$B$67=D34)*(RIGHT('Ignacio Flores'!$A$13:$A$67,1)="M")*VALUE("0"&SUBSTITUTE(SUBSTITUTE(UPPER('Ignacio Flores'!$A$13:$A$67),"F",""),"M","")))=77,SUMPRODUCT(('Ignacio Flores'!$B$13:$B$67=D34)*(RIGHT('Ignacio Flores'!$A$13:$A$67,1)="M")*VALUE("0"&SUBSTITUTE(SUBSTITUTE(UPPER('Ignacio Flores'!$A$13:$A$67),"F",""),"M",""))^2)=875),"✔ Verificado","✖ Revisar"),"✖ Revisar") -> ✖ Revisar
A35: Ignacio Flores | B35: IGNACIO FLORES | C35: 6322 | D35: U.E. JOSE MARIA VELASCO IBARRA | E35: 3150 | F35: =SUMIFS('Ignacio Flores'!$E$5:$E$9,'Ignacio Flores'!$B$5:$B$9,D35) -> 3150 | G35: 5 | H35: =COUNTIFS('Ignacio Flores'!$B$13:$B$67,D35,'Ignacio Flores'!$A$13:$A$67,"*F") -> 5 | I35: 4 | J35: =COUNTIFS('Ignacio Flores'!$B$13:$B$67,D35,'Ignacio Flores'!$A$13:$A$67,"*M") -> 4 | K35: 17F – 21F | L35: =IFERROR(IF(H35=0,"—",(1000-SUMPRODUCT(MAX(('Ignacio Flores'!$B$13:$B$67=D35)*(RIGHT('Ignacio Flores'!$A$13:$A$67,1)="F")*(1000-VALUE("0"&SUBSTITUTE(SUBSTITUTE(UPPER('Ignacio Flores'!$A$13:$A$67),"F",""),"M",""))))))&"F – "&SUMPRODUCT(MAX(('Ignacio Flores'!$B$13:$B$67=D35)*(RIGHT('Ignacio Flores'!$A$13:$A$67,1)="F")*VALUE("0"&SUBSTITUTE(SUBSTITUTE(UPPER('Ignacio Flores'!$A$13:$A$67),"F",""),"M",""))))&"F"),"✖ error") -> 16F – 16F | M35: 15M – 18M | N35: =IFERROR(IF(J35=0,"—",(1000-SUMPRODUCT(MAX(('Ignacio Flores'!$B$13:$B$67=D35)*(RIGHT('Ignacio Flores'!$A$13:$A$67,1)="M")*(1000-VALUE("0"&SUBSTITUTE(SUBSTITUTE(UPPER('Ignacio Flores'!$A$13:$A$67),"F",""),"M",""))))))&"M – "&SUMPRODUCT(MAX(('Ignacio Flores'!$B$13:$B$67=D35)*(RIGHT('Ignacio Flores'!$A$13:$A$67,1)="M")*VALUE("0"&SUBSTITUTE(SUBSTITUTE(UPPER('Ignacio Flores'!$A$13:$A$67),"F",""),"M",""))))&"M"),"✖ error") -> 1000M – 0M | O35: 9 | P35: =IFERROR(IF(AND(E35=F35,G35=H35,I35=J35,K35=L35,M35=N35,SUMPRODUCT(('Ignacio Flores'!$B$13:$B$67=D35)*(RIGHT('Ignacio Flores'!$A$13:$A$67,1)="F"))=5,SUMPRODUCT(('Ignacio Flores'!$B$13:$B$67=D35)*(RIGHT('Ignacio Flores'!$A$13:$A$67,1)="F")*VALUE("0"&SUBSTITUTE(SUBSTITUTE(UPPER('Ignacio Flores'!$A$13:$A$67),"F",""),"M","")))=95,SUMPRODUCT(('Ignacio Flores'!$B$13:$B$67=D35)*(RIGHT('Ignacio Flores'!$A$13:$A$67,1)="F")*VALUE("0"&SUBSTITUTE(SUBSTITUTE(UPPER('Ignacio Flores'!$A$13:$A$67),"F",""),"M",""))^2)=1815,SUMPRODUCT(('Ignacio Flores'!$B$13:$B$67=D35)*(RIGHT('Ignacio Flores'!$A$13:$A$67,1)="M"))=4,SUMPRODUCT(('Ignacio Flores'!$B$13:$B$67=D35)*(RIGHT('Ignacio Flores'!$A$13:$A$67,1)="M")*VALUE("0"&SUBSTITUTE(SUBSTITUTE(UPPER('Ignacio Flores'!$A$13:$A$67),"F",""),"M","")))=66,SUMPRODUCT(('Ignacio Flores'!$B$13:$B$67=D35)*(RIGHT('Ignacio Flores'!$A$13:$A$67,1)="M")*VALUE("0"&SUBSTITUTE(SUBSTITUTE(UPPER('Ignacio Flores'!$A$13:$A$67),"F",""),"M",""))^2)=1094),"✔ Verificado","✖ Revisar"),"✖ Revisar") -> ✖ Revisar
A36: Ignacio Flores | B36: IGNACIO FLORES | C36: 6332 | D36: UNIDAD EDUCATIVA RAMON BARBA NARANJO/ CENTRO | E36: 4659 | F36: =SUMIFS('Ignacio Flores'!$E$5:$E$9,'Ignacio Flores'!$B$5:$B$9,D36) -> 4659 | G36: 7 | H36: =COUNTIFS('Ignacio Flores'!$B$13:$B$67,D36,'Ignacio Flores'!$A$13:$A$67,"*F") -> 7 | I36: 7 | J36: =COUNTIFS('Ignacio Flores'!$B$13:$B$67,D36,'Ignacio Flores'!$A$13:$A$67,"*M") -> 7 | K36: 22F – 28F | L36: =IFERROR(IF(H36=0,"—",(1000-SUMPRODUCT(MAX(('Ignacio Flores'!$B$13:$B$67=D36)*(RIGHT('Ignacio Flores'!$A$13:$A$67,1)="F")*(1000-VALUE("0"&SUBSTITUTE(SUBSTITUTE(UPPER('Ignacio Flores'!$A$13:$A$67),"F",""),"M",""))))))&"F – "&SUMPRODUCT(MAX(('Ignacio Flores'!$B$13:$B$67=D36)*(RIGHT('Ignacio Flores'!$A$13:$A$67,1)="F")*VALUE("0"&SUBSTITUTE(SUBSTITUTE(UPPER('Ignacio Flores'!$A$13:$A$67),"F",""),"M",""))))&"F"),"✖ error") -> 1000F – 0F | M36: 19M – 25M | N36: =IFERROR(IF(J36=0,"—",(1000-SUMPRODUCT(MAX(('Ignacio Flores'!$B$13:$B$67=D36)*(RIGHT('Ignacio Flores'!$A$13:$A$67,1)="M")*(1000-VALUE("0"&SUBSTITUTE(SUBSTITUTE(UPPER('Ignacio Flores'!$A$13:$A$67),"F",""),"M",""))))))&"M – "&SUMPRODUCT(MAX(('Ignacio Flores'!$B$13:$B$67=D36)*(RIGHT('Ignacio Flores'!$A$13:$A$67,1)="M")*VALUE("0"&SUBSTITUTE(SUBSTITUTE(UPPER('Ignacio Flores'!$A$13:$A$67),"F",""),"M",""))))&"M"),"✖ error") -> 8M – 8M | O36: 14 | P36: =IFERROR(IF(AND(E36=F36,G36=H36,I36=J36,K36=L36,M36=N36,SUMPRODUCT(('Ignacio Flores'!$B$13:$B$67=D36)*(RIGHT('Ignacio Flores'!$A$13:$A$67,1)="F"))=7,SUMPRODUCT(('Ignacio Flores'!$B$13:$B$67=D36)*(RIGHT('Ignacio Flores'!$A$13:$A$67,1)="F")*VALUE("0"&SUBSTITUTE(SUBSTITUTE(UPPER('Ignacio Flores'!$A$13:$A$67),"F",""),"M","")))=175,SUMPRODUCT(('Ignacio Flores'!$B$13:$B$67=D36)*(RIGHT('Ignacio Flores'!$A$13:$A$67,1)="F")*VALUE("0"&SUBSTITUTE(SUBSTITUTE(UPPER('Ignacio Flores'!$A$13:$A$67),"F",""),"M",""))^2)=4403,SUMPRODUCT(('Ignacio Flores'!$B$13:$B$67=D36)*(RIGHT('Ignacio Flores'!$A$13:$A$67,1)="M"))=7,SUMPRODUCT(('Ignacio Flores'!$B$13:$B$67=D36)*(RIGHT('Ignacio Flores'!$A$13:$A$67,1)="M")*VALUE("0"&SUBSTITUTE(SUBSTITUTE(UPPER('Ignacio Flores'!$A$13:$A$67),"F",""),"M","")))=154,SUMPRODUCT(('Ignacio Flores'!$B$13:$B$67=D36)*(RIGHT('Ignacio Flores'!$A$13:$A$67,1)="M")*VALUE("0"&SUBSTITUTE(SUBSTITUTE(UPPER('Ignacio Flores'!$A$13:$A$67),"F",""),"M",""))^2)=3416),"✔ Verificado","✖ Revisar"),"✖ Revisar") -> ✖ Revisar
